Workbook

Sheet Summary
A1: Altcoin Perpetual Short Strategy — Trade Log Summary
A3: Strategy | B3: Short the 10 biggest 30-minute gainers each scan (fade-the-pump, short-only)
A4: Signal | B4: chg_30m — Price change %, 30 minutes
A5: Direction / Side | B5: reversion / short_only
A6: Basket size (N) | B6: 10
A7: Cost assumption | B7: 5 bps per leg (taker + slippage), applied once per trade
A8: Universe | B8: Binance USDT-margined alt perpetuals (excl. BTC/ETH), 24h volume >= $1,000,000
A9: Data window | B9: =TEXT('Period Summary'!B2,"yyyy-mm-dd")&" to "&TEXT('Period Summary'!C402,"yyyy-mm-dd")
A10: Max snapshot gap allowed | B10: 8 hours (longer gaps -- delistings/data holes -- are dropped)
A12: Total trades (fills) | B12: =COUNTA('Trade Log'!C2:C4011)
A13: Total periods (rebalances) | B13: =COUNTA('Period Summary'!A2:A402)
A14: Avg shorts per period | B14: =AVERAGE('Period Summary'!D2:D402)
A15: Period return win rate | B15: =COUNTIF('Period Summary'!E2:E402,">0")/COUNTA('Period Summary'!E2:E402)
A16: Best period return | B16: =MAX('Period Summary'!E2:E402)
A17: Worst period return | B17: =MIN('Period Summary'!E2:E402)
A18: Total return (compounded) | B18: ='Period Summary'!F402-1
A19: Max drawdown | B19: =MIN('Period Summary'!H2:H402)
A20: Periods per year (annualization) | B20: =COUNTA('Period Summary'!A2:A402)/(('Period Summary'!C402-'Period Summary'!B2))*365.25
A21: Annualized Sharpe (period returns) | B21: =AVERAGE('Period Summary'!E2:E402)/STDEV('Period Summary'!E2:E402)*SQRT(B20)
A24: Note: this replays historical BI screener snapshots with a fixed cost assumption; it is a backtest, not live execution. See ../RESULTS.md for full walk-forward validation, cost/liquidity sensitivity, and caveats (funding rate not modeled, short-squeeze risk, thin-liquidity slippage).

Sheet Trade Log
A1: Entry Time | B1: Exit Time | C1: Symbol | D1: Side | E1: Signal (chg_30m %) | F1: Entry Price | G1: Exit Price | H1: Gross Return % | I1: Cost % | J1: Net Return %
A2: 46204.311 | B2: 46204.362 | C2: MMTUSDT.P | D2: short | E2: 0.021937843 | F2: 0.1678 | G2: 0.1659 | H2: 0.011323004 | I2: 0.0005 | J2: 0.010823004
A3: 46204.311 | B3: 46204.362 | C3: BTWUSDT.P | D3: short | E3: 0.024677297 | F3: 0.05396 | G3: 0.05963 | H3: -0.10507784 | I3: 0.0005 | J3: -0.10557784
A4: 46204.311 | B4: 46204.362 | C4: MEUSDT.P | D4: short | E4: 0.025013305 | F4: 0.05772 | G4: 0.05859 | H4: -0.015072765 | I4: 0.0005 | J4: -0.015572765
A5: 46204.311 | B5: 46204.362 | C5: BASEDUSDT.P | D5: short | E5: 0.026857654 | F5: 0.1035 | G5: 0.10337 | H5: 0.0012560386 | I5: 0.0005 | J5: 0.00075603865
A6: 46204.311 | B6: 46204.362 | C6: TAIKOUSDT.P | D6: short | E6: 0.029150824 | F6: 0.081 | G6: 0.0789 | H6: 0.025925926 | I6: 0.0005 | J6: 0.025425926
A7: 46204.311 | B7: 46204.362 | C7: TACUSDT.P | D7: short | E7: 0.034879626 | F7: 0.064591 | G7: 0.063719 | H7: 0.013500333 | I7: 0.0005 | J7: 0.013000333
A8: 46204.311 | B8: 46204.362 | C8: ONGUSDT.P | D8: short | E8: 0.036949517 | F8: 0.04825 | G8: 0.04503 | H8: 0.066735751 | I8: 0.0005 | J8: 0.066235751
A9: 46204.311 | B9: 46204.362 | C9: XNYUSDT.P | D9: short | E9: 0.039739991 | F9: 0.007083 | G9: 0.005697 | H9: 0.1956798 | I9: 0.0005 | J9: 0.1951798
A10: 46204.311 | B10: 46204.362 | C10: LAUSDT.P | D10: short | E10: 0.040461461 | F10: 0.06217 | G10: 0.05906 | H10: 0.050024127 | I10: 0.0005 | J10: 0.049524127
A11: 46204.311 | B11: 46204.362 | C11: CLOUSDT.P | D11: short | E11: 0.05767648 | F11: 0.16853 | G11: 0.14453 | H11: 0.14240788 | I11: 0.0005 | J11: 0.14190788
A12: 46204.362 | B12: 46204.522 | C12: MYXUSDT.P | D12: short | E12: 0.016759777 | F12: 0.0909 | G12: 0.0917 | H12: -0.0088008801 | I12: 0.0005 | J12: -0.0093008801
A13: 46204.362 | B13: 46204.522 | C13: PLUMEUSDT.P | D13: short | E13: 0.017057569 | F13: 0.00955 | G13: 0.00972 | H13: -0.017801047 | I13: 0.0005 | J13: -0.018301047
... A4011: 46265.732 | B4011: 46265.915 | C4011: 0GUSDT.P | D4011: short | E4011: 0.024813896 | F4011: 0.2064 | G4011: 0.207 | H4011: -0.0029069767 | I4011: 0.0005 | J4011: -0.0034069767

Sheet Period Summary
A1: Period # | B1: Entry Time | C1: Exit Time | D1: # Shorts | E1: Period Return % | F1: Equity (start=1.0) | G1: Running Max | H1: Drawdown %
A2: 1 | B2: 46204.311 | C2: 46204.362 | D2: 10 | E2: =AVERAGE('Trade Log'!J2:J11) | F2: =IF(A2=1,1+E2,F1*(1+E2)) | G2: =F2 | H2: =F2/G2-1
A3: 2 | B3: 46204.362 | C3: 46204.522 | D3: 10 | E3: =AVERAGE('Trade Log'!J12:J21) | F3: =IF(A3=1,1+E3,F2*(1+E3)) | G3: =MAX(G2,F3) | H3: =F3/G3-1
A4: 3 | B4: 46204.522 | C4: 46204.615 | D4: 10 | E4: =AVERAGE('Trade Log'!J22:J31) | F4: =IF(A4=1,1+E4,F3*(1+E4)) | G4: =MAX(G3,F4) | H4: =F4/G4-1
A5: 4 | B5: 46204.615 | C5: 46204.753 | D5: 10 | E5: =AVERAGE('Trade Log'!J32:J41) | F5: =IF(A5=1,1+E5,F4*(1+E5)) | G5: =MAX(G4,F5) | H5: =F5/G5-1
A6: 5 | B6: 46204.753 | C6: 46204.867 | D6: 10 | E6: =AVERAGE('Trade Log'!J42:J51) | F6: =IF(A6=1,1+E6,F5*(1+E6)) | G6: =MAX(G5,F6) | H6: =F6/G6-1
A7: 6 | B7: 46204.867 | C7: 46204.944 | D7: 10 | E7: =AVERAGE('Trade Log'!J52:J61) | F7: =IF(A7=1,1+E7,F6*(1+E7)) | G7: =MAX(G6,F7) | H7: =F7/G7-1
A8: 7 | B8: 46204.944 | C8: 46205.269 | D8: 10 | E8: =AVERAGE('Trade Log'!J62:J71) | F8: =IF(A8=1,1+E8,F7*(1+E8)) | G8: =MAX(G7,F8) | H8: =F8/G8-1
A9: 8 | B9: 46205.269 | C9: 46205.366 | D9: 10 | E9: =AVERAGE('Trade Log'!J72:J81) | F9: =IF(A9=1,1+E9,F8*(1+E9)) | G9: =MAX(G8,F9) | H9: =F9/G9-1
A10: 9 | B10: 46205.366 | C10: 46205.503 | D10: 10 | E10: =AVERAGE('Trade Log'!J82:J91) | F10: =IF(A10=1,1+E10,F9*(1+E10)) | G10: =MAX(G9,F10) | H10: =F10/G10-1
A11: 10 | B11: 46205.503 | C11: 46205.769 | D11: 10 | E11: =AVERAGE('Trade Log'!J92:J101) | F11: =IF(A11=1,1+E11,F10*(1+E11)) | G11: =MAX(G10,F11) | H11: =F11/G11-1
A12: 11 | B12: 46205.769 | C12: 46205.881 | D12: 10 | E12: =AVERAGE('Trade Log'!J102:J111) | F12: =IF(A12=1,1+E12,F11*(1+E12)) | G12: =MAX(G11,F12) | H12: =F12/G12-1
A13: 12 | B13: 46205.881 | C13: 46205.946 | D13: 10 | E13: =AVERAGE('Trade Log'!J112:J121) | F13: =IF(A13=1,1+E13,F12*(1+E13)) | G13: =MAX(G12,F13) | H13: =F13/G13-1
A14: 13 | B14: 46205.946 | C14: 46206.265 | D14: 10 | E14: =AVERAGE('Trade Log'!J122:J131) | F14: =IF(A14=1,1+E14,F13*(1+E14)) | G14: =MAX(G13,F14) | H14: =F14/G14-1
A15: 14 | B15: 46206.265 | C15: 46206.385 | D15: 10 | E15: =AVERAGE('Trade Log'!J132:J141) | F15: =IF(A15=1,1+E15,F14*(1+E15)) | G15: =MAX(G14,F15) | H15: =F15/G15-1
A16: 15 | B16: 46206.385 | C16: 46206.502 | D16: 10 | E16: =AVERAGE('Trade Log'!J142:J151) | F16: =IF(A16=1,1+E16,F15*(1+E16)) | G16: =MAX(G15,F16) | H16: =F16/G16-1
A17: 16 | B17: 46206.502 | C17: 46206.61 | D17: 10 | E17: =AVERAGE('Trade Log'!J152:J161) | F17: =IF(A17=1,1+E17,F16*(1+E17)) | G17: =MAX(G16,F17) | H17: =F17/G17-1
A18: 17 | B18: 46206.61 | C18: 46206.74 | D18: 10 | E18: =AVERAGE('Trade Log'!J162:J171) | F18: =IF(A18=1,1+E18,F17*(1+E18)) | G18: =MAX(G17,F18) | H18: =F18/G18-1
A19: 18 | B19: 46206.74 | C19: 46206.881 | D19: 10 | E19: =AVERAGE('Trade Log'!J172:J181) | F19: =IF(A19=1,1+E19,F18*(1+E19)) | G19: =MAX(G18,F19) | H19: =F19/G19-1
A20: 19 | B20: 46206.881 | C20: 46206.957 | D20: 10 | E20: =AVERAGE('Trade Log'!J182:J191) | F20: =IF(A20=1,1+E20,F19*(1+E20)) | G20: =MAX(G19,F20) | H20: =F20/G20-1
A21: 20 | B21: 46206.957 | C21: 46207.281 | D21: 10 | E21: =AVERAGE('Trade Log'!J192:J201) | F21: =IF(A21=1,1+E21,F20*(1+E21)) | G21: =MAX(G20,F21) | H21: =F21/G21-1
A22: 21 | B22: 46207.281 | C22: 46207.354 | D22: 10 | E22: =AVERAGE('Trade Log'!J202:J211) | F22: =IF(A22=1,1+E22,F21*(1+E22)) | G22: =MAX(G21,F22) | H22: =F22/G22-1
A23: 22 | B23: 46207.354 | C23: 46207.477 | D23: 10 | E23: =AVERAGE('Trade Log'!J212:J221) | F23: =IF(A23=1,1+E23,F22*(1+E23)) | G23: =MAX(G22,F23) | H23: =F23/G23-1
A24: 23 | B24: 46207.477 | C24: 46207.613 | D24: 10 | E24: =AVERAGE('Trade Log'!J222:J231) | F24: =IF(A24=1,1+E24,F23*(1+E24)) | G24: =MAX(G23,F24) | H24: =F24/G24-1
A25: 24 | B25: 46207.613 | C25: 46207.702 | D25: 10 | E25: =AVERAGE('Trade Log'!J232:J241) | F25: =IF(A25=1,1+E25,F24*(1+E25)) | G25: =MAX(G24,F25) | H25: =F25/G25-1
A26: 25 | B26: 46207.702 | C26: 46207.864 | D26: 10 | E26: =AVERAGE('Trade Log'!J242:J251) | F26: =IF(A26=1,1+E26,F25*(1+E26)) | G26: =MAX(G25,F26) | H26: =F26/G26-1
A27: 26 | B27: 46207.864 | C27: 46207.978 | D27: 10 | E27: =AVERAGE('Trade Log'!J252:J261) | F27: =IF(A27=1,1+E27,F26*(1+E27)) | G27: =MAX(G26,F27) | H27: =F27/G27-1
A28: 27 | B28: 46207.978 | C28: 46208.285 | D28: 10 | E28: =AVERAGE('Trade Log'!J262:J271) | F28: =IF(A28=1,1+E28,F27*(1+E28)) | G28: =MAX(G27,F28) | H28: =F28/G28-1
A29: 28 | B29: 46208.285 | C29: 46208.381 | D29: 10 | E29: =AVERAGE('Trade Log'!J272:J281) | F29: =IF(A29=1,1+E29,F28*(1+E29)) | G29: =MAX(G28,F29) | H29: =F29/G29-1
A30: 29 | B30: 46208.381 | C30: 46208.489 | D30: 10 | E30: =AVERAGE('Trade Log'!J282:J291) | F30: =IF(A30=1,1+E30,F29*(1+E30)) | G30: =MAX(G29,F30) | H30: =F30/G30-1
A31: 30 | B31: 46208.489 | C31: 46208.614 | D31: 10 | E31: =AVERAGE('Trade Log'!J292:J301) | F31: =IF(A31=1,1+E31,F30*(1+E31)) | G31: =MAX(G30,F31) | H31: =F31/G31-1
A32: 31 | B32: 46208.614 | C32: 46208.738 | D32: 10 | E32: =AVERAGE('Trade Log'!J302:J311) | F32: =IF(A32=1,1+E32,F31*(1+E32)) | G32: =MAX(G31,F32) | H32: =F32/G32-1
A33: 32 | B33: 46208.738 | C33: 46208.863 | D33: 10 | E33: =AVERAGE('Trade Log'!J312:J321) | F33: =IF(A33=1,1+E33,F32*(1+E33)) | G33: =MAX(G32,F33) | H33: =F33/G33-1
A34: 33 | B34: 46208.863 | C34: 46208.954 | D34: 10 | E34: =AVERAGE('Trade Log'!J322:J331) | F34: =IF(A34=1,1+E34,F33*(1+E34)) | G34: =MAX(G33,F34) | H34: =F34/G34-1
A35: 34 | B35: 46208.954 | C35: 46209.282 | D35: 10 | E35: =AVERAGE('Trade Log'!J332:J341) | F35: =IF(A35=1,1+E35,F34*(1+E35)) | G35: =MAX(G34,F35) | H35: =F35/G35-1
A36: 35 | B36: 46209.282 | C36: 46209.426 | D36: 10 | E36: =AVERAGE('Trade Log'!J342:J351) | F36: =IF(A36=1,1+E36,F35*(1+E36)) | G36: =MAX(G35,F36) | H36: =F36/G36-1
A37: 36 | B37: 46209.426 | C37: 46209.492 | D37: 10 | E37: =AVERAGE('Trade Log'!J352:J361) | F37: =IF(A37=1,1+E37,F36*(1+E37)) | G37: =MAX(G36,F37) | H37: =F37/G37-1
A38: 37 | B38: 46209.492 | C38: 46209.664 | D38: 10 | E38: =AVERAGE('Trade Log'!J362:J371) | F38: =IF(A38=1,1+E38,F37*(1+E38)) | G38: =MAX(G37,F38) | H38: =F38/G38-1
A39: 38 | B39: 46209.664 | C39: 46209.743 | D39: 10 | E39: =AVERAGE('Trade Log'!J372:J381) | F39: =IF(A39=1,1+E39,F38*(1+E39)) | G39: =MAX(G38,F39) | H39: =F39/G39-1
A40: 39 | B40: 46209.743 | C40: 46209.859 | D40: 10 | E40: =AVERAGE('Trade Log'!J382:J391) | F40: =IF(A40=1,1+E40,F39*(1+E40)) | G40: =MAX(G39,F40) | H40: =F40/G40-1
...
